<?xml version="1.0" encoding="utf-8"?>
<!-- This URDF was automatically created by SolidWorks to URDF Exporter! Originally created by Stephen Brawner (brawner@gmail.com) 
     Commit Version: 1.6.0-4-g7f85cfe  Build Version: 1.6.7995.38578
     For more information, please see http://wiki.ros.org/sw_urdf_exporter -->
<robot
  name="CIARAFINAL">
  <link
    name="base_link">
    <inertial>
      <origin
        xyz="-6.7028E-35 1.7543E-18 0.035279"
        rpy="0 0 0" />
      <mass
        value="0.39708" />
      <inertia
        ixx="0.00039044"
        ixy="5.3877E-37"
        ixz="-1.1957E-36"
        iyy="0.00039044"
        iyz="1.0321E-20"
        izz="0.00032938" />
    </inertial>
    <visual>
      <origin
        xyz="0 0 0"
        rpy="0 0 0" />
      <geometry>
        <mesh
          filename="package://CIARAFINAL/meshes/base_link.STL" />
      </geometry>
      <material
        name="">
        <color
          rgba="0.79216 0.81961 0.93333 1" />
      </material>
    </visual>
    <collision>
      <origin
        xyz="0 0 0"
        rpy="0 0 0" />
      <geometry>
        <mesh
          filename="package://CIARAFINAL/meshes/base_link.STL" />
      </geometry>
    </collision>
  </link>
  <link
    name="link_0">
    <inertial>
      <origin
        xyz="0.0042585 0.00134 0.091053"
        rpy="0 0 0" />
      <mass
        value="0.32131" />
      <inertia
        ixx="0.00028822"
        ixy="-7.887E-06"
        ixz="7.2737E-08"
        iyy="0.0003108"
        iyz="2.2912E-08"
        izz="0.00018994" />
    </inertial>
    <visual>
      <origin
        xyz="0 0 0"
        rpy="0 0 0" />
      <geometry>
        <mesh
          filename="package://CIARAFINAL/meshes/link_0.STL" />
      </geometry>
      <material
        name="">
        <color
          rgba="0.79216 0.81961 0.93333 1" />
      </material>
    </visual>
    <collision>
      <origin
        xyz="0 0 0"
        rpy="0 0 0" />
      <geometry>
        <mesh
          filename="package://CIARAFINAL/meshes/link_0.STL" />
      </geometry>
    </collision>
  </link>
  <joint
    name="joint_0"
    type="revolute">
    <origin
      xyz="0 0 0.041"
      rpy="0 0 0" />
    <parent
      link="base_link" />
    <child
      link="link_0" />
    <axis
      xyz="0 0 1" />
    <limit
      lower="-1.571"
      upper="1.571"
      effort="3.9227"
      velocity="3" />
  </joint>
  <link
    name="link_1">
    <inertial>
      <origin
        xyz="-4.4858E-18 0.081 0.071963"
        rpy="0 0 0" />
      <mass
        value="0.70536" />
      <inertia
        ixx="0.0030879"
        ixy="3.7216E-10"
        ixz="4.1741E-10"
        iyy="0.0003745"
        iyz="4.4167E-20"
        izz="0.0030672" />
    </inertial>
    <visual>
      <origin
        xyz="0 0 0"
        rpy="0 0 0" />
      <geometry>
        <mesh
          filename="package://CIARAFINAL/meshes/link_1.STL" />
      </geometry>
      <material
        name="">
        <color
          rgba="0.79216 0.81961 0.93333 1" />
      </material>
    </visual>
    <collision>
      <origin
        xyz="0 0 0"
        rpy="0 0 0" />
      <geometry>
        <mesh
          filename="package://CIARAFINAL/meshes/link_1.STL" />
      </geometry>
    </collision>
  </link>
  <joint
    name="joint_1"
    type="revolute">
    <origin
      xyz="0 0 0.091"
      rpy="1.5708 0 1.8757" />
    <parent
      link="link_0" />
    <child
      link="link_1" />
    <axis
      xyz="0 0 1" />
    <limit
      lower="-1.571"
      upper="1.571"
      effort="3.9227"
      velocity="3" />
  </joint>
  <link
    name="link_2">
    <inertial>
      <origin
        xyz="-5.0307E-17 0.081 0.062032"
        rpy="0 0 0" />
      <mass
        value="0.70379" />
      <inertia
        ixx="0.003076"
        ixy="5.0576E-10"
        ixz="1.5235E-10"
        iyy="0.00037297"
        iyz="1.8011E-10"
        izz="0.0030569" />
    </inertial>
    <visual>
      <origin
        xyz="0 0 0"
        rpy="0 0 0" />
      <geometry>
        <mesh
          filename="package://CIARAFINAL/meshes/link_2.STL" />
      </geometry>
      <material
        name="">
        <color
          rgba="0.79216 0.81961 0.93333 1" />
      </material>
    </visual>
    <collision>
      <origin
        xyz="0 0 0"
        rpy="0 0 0" />
      <geometry>
        <mesh
          filename="package://CIARAFINAL/meshes/link_2.STL" />
      </geometry>
    </collision>
  </link>
  <joint
    name="joint_2"
    type="revolute">
    <origin
      xyz="0 0.162 0.072"
      rpy="-3.1416 0 3.1416" />
    <parent
      link="link_1" />
    <child
      link="link_2" />
    <axis
      xyz="0 0 1" />
    <limit
      lower="-2.269"
      upper="2.269"
      effort="1.9613"
      velocity="3" />
  </joint>
  <link
    name="link_3">
    <inertial>
      <origin
        xyz="2.4951E-09 0.0061951 0.061943"
        rpy="0 0 0" />
      <mass
        value="0.23152" />
      <inertia
        ixx="0.00015428"
        ixy="-5.0414E-11"
        ixz="-5.5275E-12"
        iyy="0.00012922"
        iyz="-8.1504E-08"
        izz="0.00014394" />
    </inertial>
    <visual>
      <origin
        xyz="0 0 0"
        rpy="0 0 0" />
      <geometry>
        <mesh
          filename="package://CIARAFINAL/meshes/link_3.STL" />
      </geometry>
      <material
        name="">
        <color
          rgba="0.79216 0.81961 0.93333 1" />
      </material>
    </visual>
    <collision>
      <origin
        xyz="0 0 0"
        rpy="0 0 0" />
      <geometry>
        <mesh
          filename="package://CIARAFINAL/meshes/link_3.STL" />
      </geometry>
    </collision>
  </link>
  <joint
    name="joint_3"
    type="revolute">
    <origin
      xyz="0 0.162 0.062"
      rpy="3.1416 0 3.1416" />
    <parent
      link="link_2" />
    <child
      link="link_3" />
    <axis
      xyz="0 0 1" />
    <limit
      lower="-1.92"
      upper="1.92"
      effort="1.0787"
      velocity="3" />
  </joint>
  <link
    name="end">
    <inertial>
      <origin
        xyz="-7.1715E-06 -8.0893E-06 0.040568"
        rpy="0 0 0" />
      <mass
        value="0.033458" />
      <inertia
        ixx="1.4757E-05"
        ixy="-3.3809E-12"
        ixz="1.7576E-08"
        iyy="1.4757E-05"
        iyz="1.9827E-08"
        izz="1.4531E-05" />
    </inertial>
    <visual>
      <origin
        xyz="0 0 0"
        rpy="0 0 0" />
      <geometry>
        <mesh
          filename="package://CIARAFINAL/meshes/end.STL" />
      </geometry>
      <material
        name="">
        <color
          rgba="0.79216 0.81961 0.93333 1" />
      </material>
    </visual>
    <collision>
      <origin
        xyz="0 0 0"
        rpy="0 0 0" />
      <geometry>
        <mesh
          filename="package://CIARAFINAL/meshes/end.STL" />
      </geometry>
    </collision>
  </link>
  <joint
    name="joint_4"
    type="revolute">
    <origin
      xyz="0 0 0.062"
      rpy="1.5708 0 -3.1416" />
    <parent
      link="link_3" />
    <child
      link="end" />
    <axis
      xyz="0 0 1" />
    <limit
      lower="-1.92"
      upper="1.92"
      effort="1.0787"
      velocity="3" />
  </joint>
</robot>