<?xml version="1.0" encoding="utf-8"?>
<!-- This URDF was automatically created by SolidWorks to URDF Exporter! Originally created by Stephen Brawner (brawner@gmail.com) 
     Commit Version: 1.6.0-4-g7f85cfe  Build Version: 1.6.7995.38578
     For more information, please see http://wiki.ros.org/sw_urdf_exporter -->
<robot
  name="ciara6">
  <link
    name="base_link">
    <inertial>
      <origin
        xyz="-5.3047E-35 0.033905 1.1704E-18"
        rpy="0 0 0" />
      <mass
        value="0.34784" />
      <inertia
        ixx="0.00030423"
        ixy="-9.4382E-37"
        ixz="-3.5725E-37"
        iyy="0.00026302"
        iyz="4.9311E-21"
        izz="0.00030423" />
    </inertial>
    <visual>
      <origin
        xyz="0 0 0"
        rpy="0 0 0" />
      <geometry>
        <mesh
          filename="package://ciara6/meshes/base_link.STL" />
      </geometry>
      <material
        name="">
        <color
          rgba="0.79216 0.81961 0.93333 1" />
      </material>
    </visual>
    <collision>
      <origin
        xyz="0 0 0"
        rpy="0 0 0" />
      <geometry>
        <mesh
          filename="package://ciara6/meshes/base_link.STL" />
      </geometry>
    </collision>
  </link>
  <link
    name="link_1">
    <inertial>
      <origin
        xyz="0.0053016 1.7101E-05 0.084795"
        rpy="0 0 0" />
      <mass
        value="0.32209" />
      <inertia
        ixx="0.00027535"
        ixy="-1.1347E-07"
        ixz="2.0251E-06"
        iyy="0.00031023"
        iyz="6.6064E-09"
        izz="0.00019728" />
    </inertial>
    <visual>
      <origin
        xyz="0 0 0"
        rpy="0 0 0" />
      <geometry>
        <mesh
          filename="package://ciara6/meshes/link_1.STL" />
      </geometry>
      <material
        name="">
        <color
          rgba="0.79216 0.81961 0.93333 1" />
      </material>
    </visual>
    <collision>
      <origin
        xyz="0 0 0"
        rpy="0 0 0" />
      <geometry>
        <mesh
          filename="package://ciara6/meshes/link_1.STL" />
      </geometry>
    </collision>
  </link>
  <joint
    name="jnt_1"
    type="revolute">
    <origin
      xyz="0 0 0.04"
      rpy="0 0 0" />
    <parent
      link="base_link" />
    <child
      link="link_1" />
    <axis
      xyz="0 0 1" />
    <limit
      lower="-1.5708"
      upper="1.5708"
      effort="1.96133"
      velocity="3" />
  </joint>
  <link
    name="link_2">
    <inertial>
      <origin
        xyz="0.0022102 0.085247 0.07203"
        rpy="0 0 0" />
      <mass
        value="0.74363" />
      <inertia
        ixx="0.0033845"
        ixy="-7.6454E-05"
        ixz="2.9253E-06"
        iyy="0.00043764"
        iyz="0.00011281"
        izz="0.0033235" />
    </inertial>
    <visual>
      <origin
        xyz="0 0 0"
        rpy="0 0 0" />
      <geometry>
        <mesh
          filename="package://ciara6/meshes/link_2.STL" />
      </geometry>
      <material
        name="">
        <color
          rgba="0.79216 0.81961 0.93333 1" />
      </material>
    </visual>
    <collision>
      <origin
        xyz="0 0 0"
        rpy="0 0 0" />
      <geometry>
        <mesh
          filename="package://ciara6/meshes/link_2.STL" />
      </geometry>
    </collision>
  </link>
  <joint
    name="jnt_2"
    type="revolute">
    <origin
      xyz="0 0 0.083609"
      rpy="1.5708 0 1.574" />
    <parent
      link="link_1" />
    <child
      link="link_2" />
    <axis
      xyz="0 0 -1" />
    <limit
      lower="-1.5708"
      upper="1.5708"
      effort="3.92266"
      velocity="3" />
  </joint>
  <link
    name="link_3">
    <inertial>
      <origin
        xyz="0.00064205 0.076724 0.086012"
        rpy="0 0 0" />
      <mass
        value="0.74403" />
      <inertia
        ixx="0.0033894"
        ixy="-2.4714E-05"
        ixz="-9.46E-07"
        iyy="0.00043638"
        iyz="-0.00011299"
        izz="0.0033261" />
    </inertial>
    <visual>
      <origin
        xyz="0 0 0"
        rpy="0 0 0" />
      <geometry>
        <mesh
          filename="package://ciara6/meshes/link_3.STL" />
      </geometry>
      <material
        name="">
        <color
          rgba="0.79216 0.81961 0.93333 1" />
      </material>
    </visual>
    <collision>
      <origin
        xyz="0 0 0"
        rpy="0 0 0" />
      <geometry>
        <mesh
          filename="package://ciara6/meshes/link_3.STL" />
      </geometry>
    </collision>
  </link>
  <joint
    name="jnt_3"
    type="revolute">
    <origin
      xyz="0.0041987 0.16195 0.074"
      rpy="-3.1416 0 3.1416" />
    <parent
      link="link_2" />
    <child
      link="link_3" />
    <axis
      xyz="0 0 -1" />
    <limit
      lower="-2.3562"
      upper="2.3562"
      effort="3.9227"
      velocity="3" />
  </joint>
  <link
    name="link_4">
    <inertial>
      <origin
        xyz="-7.4895E-10 0.0099327 -0.035034"
        rpy="0 0 0" />
      <mass
        value="0.28528" />
      <inertia
        ixx="0.00023794"
        ixy="6.3275E-12"
        ixz="-2.4072E-11"
        iyy="0.0001749"
        iyz="-9.5075E-08"
        izz="0.00020802" />
    </inertial>
    <visual>
      <origin
        xyz="0 0 0"
        rpy="0 0 0" />
      <geometry>
        <mesh
          filename="package://ciara6/meshes/link_4.STL" />
      </geometry>
      <material
        name="">
        <color
          rgba="0.79216 0.81961 0.93333 1" />
      </material>
    </visual>
    <collision>
      <origin
        xyz="0 0 0"
        rpy="0 0 0" />
      <geometry>
        <mesh
          filename="package://ciara6/meshes/link_4.STL" />
      </geometry>
    </collision>
  </link>
  <joint
    name="jnt_4"
    type="revolute">
    <origin
      xyz="0.0013557 0.16199 -0.013"
      rpy="3.1416 0 -3.1416" />
    <parent
      link="link_3" />
    <child
      link="link_4" />
    <axis
      xyz="0 0 1" />
    <limit
      lower="-2.3562"
      upper="2.3562"
      effort="1.0787315"
      velocity="3" />
  </joint>
</robot>