<?xml version="1.0" encoding="utf-8"?>
<!-- This URDF was automatically created by SolidWorks to URDF Exporter! Originally created by Stephen Brawner (brawner@gmail.com) 
     Commit Version: 1.6.0-4-g7f85cfe  Build Version: 1.6.7995.38578
     For more information, please see http://wiki.ros.org/sw_urdf_exporter -->
<robot
  name="ciara4">
  <link
    name="base_link">
    <inertial>
      <origin
        xyz="-6.7028E-35 0.035279 4.0582E-19"
        rpy="0 0 0" />
      <mass
        value="0.39708" />
      <inertia
        ixx="0.00039044"
        ixy="-1.1957E-36"
        ixz="-5.3877E-37"
        iyy="0.00032938"
        iyz="-1.406E-20"
        izz="0.00039044" />
    </inertial>
    <visual>
      <origin
        xyz="0 0 0"
        rpy="0 0 0" />
      <geometry>
        <mesh
          filename="package://ciara4/meshes/base_link.STL" />
      </geometry>
      <material
        name="">
        <color
          rgba="0.79216 0.81961 0.93333 1" />
      </material>
    </visual>
    <collision>
      <origin
        xyz="0 0 0"
        rpy="0 0 0" />
      <geometry>
        <mesh
          filename="package://ciara4/meshes/base_link.STL" />
      </geometry>
    </collision>
  </link>
  <link
    name="link_0">
    <inertial>
      <origin
        xyz="0.0042585 0.00134 0.091053"
        rpy="0 0 0" />
      <mass
        value="0.32131" />
      <inertia
        ixx="0.00028822"
        ixy="-7.887E-06"
        ixz="7.2737E-08"
        iyy="0.0003108"
        iyz="2.2912E-08"
        izz="0.00018994" />
    </inertial>
    <visual>
      <origin
        xyz="0 0 0"
        rpy="0 0 0" />
      <geometry>
        <mesh
          filename="package://ciara4/meshes/link_0.STL" />
      </geometry>
      <material
        name="">
        <color
          rgba="0.79216 0.81961 0.93333 1" />
      </material>
    </visual>
    <collision>
      <origin
        xyz="0 0 0"
        rpy="0 0 0" />
      <geometry>
        <mesh
          filename="package://ciara4/meshes/link_0.STL" />
      </geometry>
    </collision>
  </link>
  <joint
    name="joint_0"
    type="revolute">
    <origin
      xyz="0 0 0.041"
      rpy="0 0 0" />
    <parent
      link="base_link" />
    <child
      link="link_0" />
    <axis
      xyz="0 0 1" />
    <limit
      lower="-3.1416"
      upper="3.1416"
      effort="3.9227"
      velocity="3" />
  </joint>
  <link
    name="link_1">
    <inertial>
      <origin
        xyz="-2.8772E-17 0.081 0.071963"
        rpy="0 0 0" />
      <mass
        value="0.70536" />
      <inertia
        ixx="0.0030879"
        ixy="3.7216E-10"
        ixz="4.1741E-10"
        iyy="0.0003745"
        iyz="7.5468E-20"
        izz="0.0030672" />
    </inertial>
    <visual>
      <origin
        xyz="0 0 0"
        rpy="0 0 0" />
      <geometry>
        <mesh
          filename="package://ciara4/meshes/link_1.STL" />
      </geometry>
      <material
        name="">
        <color
          rgba="0.79216 0.81961 0.93333 1" />
      </material>
    </visual>
    <collision>
      <origin
        xyz="0 0 0"
        rpy="0 0 0" />
      <geometry>
        <mesh
          filename="package://ciara4/meshes/link_1.STL" />
      </geometry>
    </collision>
  </link>
  <joint
    name="joint_1"
    type="revolute">
    <origin
      xyz="0 0 0.091"
      rpy="1.5708 0 1.8757" />
    <parent
      link="link_0" />
    <child
      link="link_1" />
    <axis
      xyz="0 0 1" />
    <limit
      lower="-2.0944"
      upper="2.0944"
      effort="3.9227"
      velocity="3" />
  </joint>
  <link
    name="link_2">
    <inertial>
      <origin
        xyz="-4.7271E-17 0.081 0.062032"
        rpy="0 0 0" />
      <mass
        value="0.70379" />
      <inertia
        ixx="0.003076"
        ixy="3.7216E-10"
        ixz="4.1741E-10"
        iyy="0.00037297"
        iyz="-1.4593E-20"
        izz="0.0030569" />
    </inertial>
    <visual>
      <origin
        xyz="0 0 0"
        rpy="0 0 0" />
      <geometry>
        <mesh
          filename="package://ciara4/meshes/link_2.STL" />
      </geometry>
      <material
        name="">
        <color
          rgba="0.79216 0.81961 0.93333 1" />
      </material>
    </visual>
    <collision>
      <origin
        xyz="0 0 0"
        rpy="0 0 0" />
      <geometry>
        <mesh
          filename="package://ciara4/meshes/link_2.STL" />
      </geometry>
    </collision>
  </link>
  <joint
    name="joint_2"
    type="revolute">
    <origin
      xyz="0 0.162 0.072"
      rpy="-3.1416 0 -3.1416" />
    <parent
      link="link_1" />
    <child
      link="link_2" />
    <axis
      xyz="0 0 1" />
    <limit
      lower="-2.4435"
      upper="2.4435"
      effort="1.9613"
      velocity="3" />
  </joint>
  <link
    name="end">
    <inertial>
      <origin
        xyz="1.5163E-08 0.0068679 0.061944"
        rpy="0 0 0" />
      <mass
        value="0.23395" />
      <inertia
        ixx="0.00016575"
        ixy="-1.5321E-10"
        ixz="-1.4129E-10"
        iyy="0.00012923"
        iyz="-1.0828E-07"
        izz="0.00015541" />
    </inertial>
    <visual>
      <origin
        xyz="0 0 0"
        rpy="0 0 0" />
      <geometry>
        <mesh
          filename="package://ciara4/meshes/end.STL" />
      </geometry>
      <material
        name="">
        <color
          rgba="0.79216 0.81961 0.93333 1" />
      </material>
    </visual>
    <collision>
      <origin
        xyz="0 0 0"
        rpy="0 0 0" />
      <geometry>
        <mesh
          filename="package://ciara4/meshes/end.STL" />
      </geometry>
    </collision>
  </link>
  <joint
    name="joint_3"
    type="revolute">
    <origin
      xyz="0 0.162 0.062"
      rpy="-3.1416 0 3.1416" />
    <parent
      link="link_2" />
    <child
      link="end" />
    <axis
      xyz="0 0 1" />
    <limit
      lower="-1.5708"
      upper="2.618"
      effort="0.98067"
      velocity="3" />
  </joint>
</robot>